2025-03-31 15:09:32.059 - INFO - api - [20250331150932059319] Processando pergunta: Quantas tabelas existem no banco de dados?...
2025-03-31 15:09:37.666 - ERROR - api - [20250331150932059319] Erro SSL ao chamar API: HTTPSConnectionPool(host='api.deepseek.com', port=443): Max retries exceeded with url: /v1/chat/completions (Caused by SSLError(SSLCertVerificationError(1, '[SSL: CERTIFICATE_VERIFY_FAILED] certificate verify failed: unable to get local issuer certificate (_ssl.c:1028)')))
2025-03-31 15:09:37.667 - ERROR - api - [20250331150932059319] Erro ao chamar DeepSeek: Problema de segurança na conexão: HTTPSConnectionPool(host='api.deepseek.com', port=443): Max retries exceeded with url: /v1/chat/completions (Caused by SSLError(SSLCertVerificationError(1, '[SSL: CERTIFICATE_VERIFY_FAILED] certificate verify failed: unable to get local issuer certificate (_ssl.c:1028)')))
Traceback (most recent call last):
  File "C:\Users\JS982PS\AppData\Local\Programs\Python\Python313\Lib\site-packages\urllib3\connectionpool.py", line 464, in _make_request
    self._validate_conn(conn)
    ~~~~~~~~~~~~~~~~~~~^^^^^^
  File "C:\Users\JS982PS\AppData\Local\Programs\Python\Python313\Lib\site-packages\urllib3\connectionpool.py", line 1093, in _validate_conn
    conn.connect()
    ~~~~~~~~~~~~^^
  File "C:\Users\JS982PS\AppData\Local\Programs\Python\Python313\Lib\site-packages\urllib3\connection.py", line 741, in connect
    sock_and_verified = _ssl_wrap_socket_and_match_hostname(
        sock=sock,
    ...<14 lines>...
        assert_fingerprint=self.assert_fingerprint,
    )
  File "C:\Users\JS982PS\AppData\Local\Programs\Python\Python313\Lib\site-packages\urllib3\connection.py", line 920, in _ssl_wrap_socket_and_match_hostname
    ssl_sock = ssl_wrap_socket(
        sock=sock,
    ...<8 lines>...
        tls_in_tls=tls_in_tls,
    )
  File "C:\Users\JS982PS\AppData\Local\Programs\Python\Python313\Lib\site-packages\urllib3\util\ssl_.py", line 460, in ssl_wrap_socket
    ssl_sock = _ssl_wrap_socket_impl(sock, context, tls_in_tls, server_hostname)
  File "C:\Users\JS982PS\AppData\Local\Programs\Python\Python313\Lib\site-packages\urllib3\util\ssl_.py", line 504, in _ssl_wrap_socket_impl
    return ssl_context.wrap_socket(sock, server_hostname=server_hostname)
           ~~~~~~~~~~~~~~~~~~~~~~~^^^^^^^^^^^^^^^^^^^^^^^^^^^^^^^^^^^^^^^
  File "C:\Users\JS982PS\AppData\Local\Programs\Python\Python313\Lib\ssl.py", line 455, in wrap_socket
    return self.sslsocket_class._create(
           ~~~~~~~~~~~~~~~~~~~~~~~~~~~~^
        sock=sock,
        ^^^^^^^^^^
    ...<5 lines>...
        session=session
        ^^^^^^^^^^^^^^^
    )
    ^
  File "C:\Users\JS982PS\AppData\Local\Programs\Python\Python313\Lib\ssl.py", line 1076, in _create
    self.do_handshake()
    ~~~~~~~~~~~~~~~~~^^
  File "C:\Users\JS982PS\AppData\Local\Programs\Python\Python313\Lib\ssl.py", line 1372, in do_handshake
    self._sslobj.do_handshake()
    ~~~~~~~~~~~~~~~~~~~~~~~~~^^
ssl.SSLCertVerificationError: [SSL: CERTIFICATE_VERIFY_FAILED] certificate verify failed: unable to get local issuer certificate (_ssl.c:1028)

During handling of the above exception, another exception occurred:

Traceback (most recent call last):
  File "C:\Users\JS982PS\AppData\Local\Programs\Python\Python313\Lib\site-packages\urllib3\connectionpool.py", line 787, in urlopen
    response = self._make_request(
        conn,
    ...<10 lines>...
        **response_kw,
    )
  File "C:\Users\JS982PS\AppData\Local\Programs\Python\Python313\Lib\site-packages\urllib3\connectionpool.py", line 488, in _make_request
    raise new_e
urllib3.exceptions.SSLError: [SSL: CERTIFICATE_VERIFY_FAILED] certificate verify failed: unable to get local issuer certificate (_ssl.c:1028)

The above exception was the direct cause of the following exception:

Traceback (most recent call last):
  File "C:\Users\JS982PS\AppData\Local\Programs\Python\Python313\Lib\site-packages\requests\adapters.py", line 667, in send
    resp = conn.urlopen(
        method=request.method,
    ...<9 lines>...
        chunked=chunked,
    )
  File "C:\Users\JS982PS\AppData\Local\Programs\Python\Python313\Lib\site-packages\urllib3\connectionpool.py", line 841, in urlopen
    retries = retries.increment(
        method, url, error=new_e, _pool=self, _stacktrace=sys.exc_info()[2]
    )
  File "C:\Users\JS982PS\AppData\Local\Programs\Python\Python313\Lib\site-packages\urllib3\util\retry.py", line 519, in increment
    raise MaxRetryError(_pool, url, reason) from reason  # type: ignore[arg-type]
    ^^^^^^^^^^^^^^^^^^^^^^^^^^^^^^^^^^^^^^^^^^^^^^^^^^^
urllib3.exceptions.MaxRetryError: HTTPSConnectionPool(host='api.deepseek.com', port=443): Max retries exceeded with url: /v1/chat/completions (Caused by SSLError(SSLCertVerificationError(1, '[SSL: CERTIFICATE_VERIFY_FAILED] certificate verify failed: unable to get local issuer certificate (_ssl.c:1028)')))

During handling of the above exception, another exception occurred:

Traceback (most recent call last):
  File "C:\Users\JS982PS\OneDrive - EY\Documents\projeto-dados\api-powerbi\api.py", line 298, in call_deepseek
    response = requests.post(
        f"{config['DEEPSEEK_API_URL']}/v1/chat/completions",
    ...<3 lines>...
        verify=certifi.where()  # Usa certificados confiáveis
    )
  File "C:\Users\JS982PS\AppData\Local\Programs\Python\Python313\Lib\site-packages\requests\api.py", line 115, in post
    return request("post", url, data=data, json=json, **kwargs)
  File "C:\Users\JS982PS\AppData\Local\Programs\Python\Python313\Lib\site-packages\requests\api.py", line 59, in request
    return session.request(method=method, url=url, **kwargs)
           ~~~~~~~~~~~~~~~^^^^^^^^^^^^^^^^^^^^^^^^^^^^^^^^^^
  File "C:\Users\JS982PS\AppData\Local\Programs\Python\Python313\Lib\site-packages\requests\sessions.py", line 589, in request
    resp = self.send(prep, **send_kwargs)
  File "C:\Users\JS982PS\AppData\Local\Programs\Python\Python313\Lib\site-packages\requests\sessions.py", line 703, in send
    r = adapter.send(request, **kwargs)
  File "C:\Users\JS982PS\AppData\Local\Programs\Python\Python313\Lib\site-packages\requests\adapters.py", line 698, in send
    raise SSLError(e, request=request)
requests.exceptions.SSLError: HTTPSConnectionPool(host='api.deepseek.com', port=443): Max retries exceeded with url: /v1/chat/completions (Caused by SSLError(SSLCertVerificationError(1, '[SSL: CERTIFICATE_VERIFY_FAILED] certificate verify failed: unable to get local issuer certificate (_ssl.c:1028)')))

During handling of the above exception, another exception occurred:

Traceback (most recent call last):
  File "C:\Users\JS982PS\OneDrive - EY\Documents\projeto-dados\api-powerbi\api.py", line 159, in ask_question
    deepseek_response = call_deepseek(prompt, request_id)
  File "C:\Users\JS982PS\OneDrive - EY\Documents\projeto-dados\api-powerbi\api.py", line 330, in call_deepseek
    raise Exception(f"Problema de segurança na conexão: {str(e)}")
Exception: Problema de segurança na conexão: HTTPSConnectionPool(host='api.deepseek.com', port=443): Max retries exceeded with url: /v1/chat/completions (Caused by SSLError(SSLCertVerificationError(1, '[SSL: CERTIFICATE_VERIFY_FAILED] certificate verify failed: unable to get local issuer certificate (_ssl.c:1028)')))
2025-04-01 09:05:53.626 - CRITICAL - api - Falha na configuração inicial: Variáveis de ambiente ausentes: OPENAI_API_KEY
Traceback (most recent call last):
  File "C:\Users\JS982PS\OneDrive - EY\Documents\projeto-dados\api-powerbi\api-openai\api.py", line 56, in load_configuration
    raise EnvironmentError(f"Variáveis de ambiente ausentes: {', '.join(missing_vars)}")
OSError: Variáveis de ambiente ausentes: OPENAI_API_KEY
2025-04-01 10:03:56.733 - CRITICAL - api - Falha na configuração inicial: Variáveis de ambiente ausentes: GEMINI_API_KEY
Traceback (most recent call last):
  File "C:\Users\JS982PS\OneDrive - EY\Documents\projeto-dados\api-powerbi\api-openai\api.py", line 68, in load_configuration
    raise EnvironmentError(f"Variáveis de ambiente ausentes: {', '.join(missing_vars)}")
OSError: Variáveis de ambiente ausentes: GEMINI_API_KEY
2025-04-01 10:47:52.393 - ERROR - api - Erro no banco de dados: relation "sua_tabela" does not exist
LINE 1: SELECT * FROM sua_tabela
                      ^
Traceback (most recent call last):
  File "C:\Users\JS982PS\OneDrive - EY\Documents\projeto-dados\api-powerbi\api-openai\api.py", line 154, in ask_question
    cur.execute("SELECT * FROM sua_tabela")  # Exemplo
    ~~~~~~~~~~~^^^^^^^^^^^^^^^^^^^^^^^^^^^^
psycopg2.errors.UndefinedTable: relation "sua_tabela" does not exist
LINE 1: SELECT * FROM sua_tabela
                      ^

2025-04-01 11:00:11.337 - ERROR - api - Erro na API Gemini: 401 Client Error: Unauthorized for url: https://generativelanguage.googleapis.com/v1beta/models/gemini-1.5-flash-latest:generateContent?key=/generate
2025-04-01 11:12:44.569 - INFO - api - Enviando para Gemini: URL=https://generativelanguage.googleapis.com/v1beta/models/gemini-1.5-flash-latest:generateContent?key=/v1/models/gemini-pro:generateContent
2025-04-01 11:12:45.583 - INFO - api - Resposta da Gemini - Status: 400
2025-04-01 11:12:45.584 - ERROR - api - Erro detalhado na requisição: 400 Client Error: Bad Request for url: https://generativelanguage.googleapis.com/v1beta/models/gemini-1.5-flash-latest:generateContent?key=/v1/models/gemini-pro:generateContent
2025-04-01 11:18:58.704 - ERROR - api - Erro ao processar resposta: 'DB_NAME'
2025-04-01 11:19:37.088 - ERROR - api - Erro ao processar resposta: 'DB_NAME'
2025-04-01 11:21:02.345 - ERROR - api - Erro ao processar resposta: 'DB_NAME'
2025-04-01 11:26:24.907 - ERROR - api - Erro não tratado [ID:20250401112624906919]: 'DB_NAME'
Traceback (most recent call last):
  File "C:\Users\JS982PS\AppData\Local\Programs\Python\Python313\Lib\site-packages\starlette\middleware\errors.py", line 165, in __call__
    await self.app(scope, receive, _send)
  File "C:\Users\JS982PS\AppData\Local\Programs\Python\Python313\Lib\site-packages\starlette\middleware\cors.py", line 85, in __call__
    await self.app(scope, receive, send)
  File "C:\Users\JS982PS\AppData\Local\Programs\Python\Python313\Lib\site-packages\starlette\middleware\exceptions.py", line 62, in __call__
    await wrap_app_handling_exceptions(self.app, conn)(scope, receive, send)
  File "C:\Users\JS982PS\AppData\Local\Programs\Python\Python313\Lib\site-packages\starlette\_exception_handler.py", line 53, in wrapped_app
    raise exc
  File "C:\Users\JS982PS\AppData\Local\Programs\Python\Python313\Lib\site-packages\starlette\_exception_handler.py", line 42, in wrapped_app
    await app(scope, receive, sender)
  File "C:\Users\JS982PS\AppData\Local\Programs\Python\Python313\Lib\site-packages\starlette\routing.py", line 714, in __call__
    await self.middleware_stack(scope, receive, send)
  File "C:\Users\JS982PS\AppData\Local\Programs\Python\Python313\Lib\site-packages\starlette\routing.py", line 734, in app
    await route.handle(scope, receive, send)
  File "C:\Users\JS982PS\AppData\Local\Programs\Python\Python313\Lib\site-packages\starlette\routing.py", line 288, in handle
    await self.app(scope, receive, send)
  File "C:\Users\JS982PS\AppData\Local\Programs\Python\Python313\Lib\site-packages\starlette\routing.py", line 76, in app
    await wrap_app_handling_exceptions(app, request)(scope, receive, send)
  File "C:\Users\JS982PS\AppData\Local\Programs\Python\Python313\Lib\site-packages\starlette\_exception_handler.py", line 53, in wrapped_app
    raise exc
  File "C:\Users\JS982PS\AppData\Local\Programs\Python\Python313\Lib\site-packages\starlette\_exception_handler.py", line 42, in wrapped_app
    await app(scope, receive, sender)
  File "C:\Users\JS982PS\AppData\Local\Programs\Python\Python313\Lib\site-packages\starlette\routing.py", line 73, in app
    response = await f(request)
               ^^^^^^^^^^^^^^^^
  File "C:\Users\JS982PS\AppData\Local\Programs\Python\Python313\Lib\site-packages\fastapi\routing.py", line 301, in app
    raw_response = await run_endpoint_function(
                   ^^^^^^^^^^^^^^^^^^^^^^^^^^^^
    ...<3 lines>...
    )
    ^
  File "C:\Users\JS982PS\AppData\Local\Programs\Python\Python313\Lib\site-packages\fastapi\routing.py", line 212, in run_endpoint_function
    return await dependant.call(**values)
           ^^^^^^^^^^^^^^^^^^^^^^^^^^^^^^
  File "C:\Users\JS982PS\OneDrive - EY\Documents\projeto-dados\api-powerbi\api-openai\api.py", line 154, in ask_question
    - Database: {config['DB_NAME']}
                 ~~~~~~^^^^^^^^^^^
KeyError: 'DB_NAME'
2025-04-01 12:05:09.433 - ERROR - api - Erro não tratado [ID:20250401120509433599]: 'DB_NAME'
Traceback (most recent call last):
  File "C:\Users\JS982PS\AppData\Local\Programs\Python\Python313\Lib\site-packages\starlette\middleware\errors.py", line 165, in __call__
    await self.app(scope, receive, _send)
  File "C:\Users\JS982PS\AppData\Local\Programs\Python\Python313\Lib\site-packages\starlette\middleware\cors.py", line 85, in __call__
    await self.app(scope, receive, send)
  File "C:\Users\JS982PS\AppData\Local\Programs\Python\Python313\Lib\site-packages\starlette\middleware\exceptions.py", line 62, in __call__
    await wrap_app_handling_exceptions(self.app, conn)(scope, receive, send)
  File "C:\Users\JS982PS\AppData\Local\Programs\Python\Python313\Lib\site-packages\starlette\_exception_handler.py", line 53, in wrapped_app
    raise exc
  File "C:\Users\JS982PS\AppData\Local\Programs\Python\Python313\Lib\site-packages\starlette\_exception_handler.py", line 42, in wrapped_app
    await app(scope, receive, sender)
  File "C:\Users\JS982PS\AppData\Local\Programs\Python\Python313\Lib\site-packages\starlette\routing.py", line 714, in __call__
    await self.middleware_stack(scope, receive, send)
  File "C:\Users\JS982PS\AppData\Local\Programs\Python\Python313\Lib\site-packages\starlette\routing.py", line 734, in app
    await route.handle(scope, receive, send)
  File "C:\Users\JS982PS\AppData\Local\Programs\Python\Python313\Lib\site-packages\starlette\routing.py", line 288, in handle
    await self.app(scope, receive, send)
  File "C:\Users\JS982PS\AppData\Local\Programs\Python\Python313\Lib\site-packages\starlette\routing.py", line 76, in app
    await wrap_app_handling_exceptions(app, request)(scope, receive, send)
  File "C:\Users\JS982PS\AppData\Local\Programs\Python\Python313\Lib\site-packages\starlette\_exception_handler.py", line 53, in wrapped_app
    raise exc
  File "C:\Users\JS982PS\AppData\Local\Programs\Python\Python313\Lib\site-packages\starlette\_exception_handler.py", line 42, in wrapped_app
    await app(scope, receive, sender)
  File "C:\Users\JS982PS\AppData\Local\Programs\Python\Python313\Lib\site-packages\starlette\routing.py", line 73, in app
    response = await f(request)
               ^^^^^^^^^^^^^^^^
  File "C:\Users\JS982PS\AppData\Local\Programs\Python\Python313\Lib\site-packages\fastapi\routing.py", line 301, in app
    raw_response = await run_endpoint_function(
                   ^^^^^^^^^^^^^^^^^^^^^^^^^^^^
    ...<3 lines>...
    )
    ^
  File "C:\Users\JS982PS\AppData\Local\Programs\Python\Python313\Lib\site-packages\fastapi\routing.py", line 212, in run_endpoint_function
    return await dependant.call(**values)
           ^^^^^^^^^^^^^^^^^^^^^^^^^^^^^^
  File "C:\Users\JS982PS\OneDrive - EY\Documents\projeto-dados\api-powerbi\api-openai\api.py", line 164, in ask_question
    - Database: {config['DB_NAME']}
                 ~~~~~~^^^^^^^^^^^
KeyError: 'DB_NAME'
2025-04-01 12:36:36.204 - ERROR - api - Erro não tratado [ID:20250401123636204701]: 'DB_NAME'
Traceback (most recent call last):
  File "C:\Users\JS982PS\AppData\Local\Programs\Python\Python313\Lib\site-packages\starlette\middleware\errors.py", line 165, in __call__
    await self.app(scope, receive, _send)
  File "C:\Users\JS982PS\AppData\Local\Programs\Python\Python313\Lib\site-packages\starlette\middleware\cors.py", line 85, in __call__
    await self.app(scope, receive, send)
  File "C:\Users\JS982PS\AppData\Local\Programs\Python\Python313\Lib\site-packages\starlette\middleware\exceptions.py", line 62, in __call__
    await wrap_app_handling_exceptions(self.app, conn)(scope, receive, send)
  File "C:\Users\JS982PS\AppData\Local\Programs\Python\Python313\Lib\site-packages\starlette\_exception_handler.py", line 53, in wrapped_app
    raise exc
  File "C:\Users\JS982PS\AppData\Local\Programs\Python\Python313\Lib\site-packages\starlette\_exception_handler.py", line 42, in wrapped_app
    await app(scope, receive, sender)
  File "C:\Users\JS982PS\AppData\Local\Programs\Python\Python313\Lib\site-packages\starlette\routing.py", line 714, in __call__
    await self.middleware_stack(scope, receive, send)
  File "C:\Users\JS982PS\AppData\Local\Programs\Python\Python313\Lib\site-packages\starlette\routing.py", line 734, in app
    await route.handle(scope, receive, send)
  File "C:\Users\JS982PS\AppData\Local\Programs\Python\Python313\Lib\site-packages\starlette\routing.py", line 288, in handle
    await self.app(scope, receive, send)
  File "C:\Users\JS982PS\AppData\Local\Programs\Python\Python313\Lib\site-packages\starlette\routing.py", line 76, in app
    await wrap_app_handling_exceptions(app, request)(scope, receive, send)
  File "C:\Users\JS982PS\AppData\Local\Programs\Python\Python313\Lib\site-packages\starlette\_exception_handler.py", line 53, in wrapped_app
    raise exc
  File "C:\Users\JS982PS\AppData\Local\Programs\Python\Python313\Lib\site-packages\starlette\_exception_handler.py", line 42, in wrapped_app
    await app(scope, receive, sender)
  File "C:\Users\JS982PS\AppData\Local\Programs\Python\Python313\Lib\site-packages\starlette\routing.py", line 73, in app
    response = await f(request)
               ^^^^^^^^^^^^^^^^
  File "C:\Users\JS982PS\AppData\Local\Programs\Python\Python313\Lib\site-packages\fastapi\routing.py", line 301, in app
    raw_response = await run_endpoint_function(
                   ^^^^^^^^^^^^^^^^^^^^^^^^^^^^
    ...<3 lines>...
    )
    ^
  File "C:\Users\JS982PS\AppData\Local\Programs\Python\Python313\Lib\site-packages\fastapi\routing.py", line 212, in run_endpoint_function
    return await dependant.call(**values)
           ^^^^^^^^^^^^^^^^^^^^^^^^^^^^^^
  File "C:\Users\JS982PS\OneDrive - EY\Documents\projeto-dados\api-powerbi\api-openai\api.py", line 174, in ask_question
    - Database: {config['DB_NAME']}
                 ~~~~~~^^^^^^^^^^^
KeyError: 'DB_NAME'
